Workbook

Sheet Capa
B2: ANTES DE FECHAR NEGÓCIO
B3: O guia do vistoriador para quem vai comprar carro usado · Protocolo Cautelar
B5: Custo total da compra
B10: COMO USAR (passo a passo)
B11: 1. Abra a aba Custo total e preencha as células AZUIS, de cima para baixo. As pretas se calculam sozinhas.
B12: 2. Taxas de transferência e licenciamento mudam de estado para estado: consulte o órgão de trânsito do seu estado e digite os valores.
B13: 3. Nos débitos do carro, marque quem vai pagar (vendedor ou comprador). Só entra na sua conta o que for do comprador.
B14: 4. Se for financiar, informe entrada, número de parcelas e taxa de juros ao mês: a planilha calcula parcela, total pago e juros.
B15: 5. No resumo você vê o dinheiro necessário no dia da compra e o custo total no 1º ano.
B16: 6. Na aba Orçamento mensal, compare quanto o carro vai custar por mês com a sua renda disponível.
B17: 7. Apague os exemplos (células azuis) antes de usar com os seus números.
B19: LEGENDA DE CORES
B20: 58.900,00 | C20: AZUL (fundo azul-claro) = você PREENCHE: digite ou escolha na lista.
B21: =2*617 | C21: PRETO = CALCULADO automaticamente. Não digite por cima.
B22: Alerta | C22: VERMELHO = sinal de alerta: pare, confira e, se preciso, chame um profissional.
B24: O preço é só uma parte: transferência, débitos, seguro, revisão, reparos, IPVA e combustível entram na conta.
B25: Os percentuais (reserva, alíquota de IPVA, limite do orçamento) são editáveis. Nada aqui é conselho financeiro.
B27: Valores de exemplo fictícios. Esta planilha organiza informações para a SUA decisão: não é recomendação de compra nem conselho financeiro e não substitui a vistoria cautelar profissional, a vistoria oficial do órgão de trânsito nem a orientação de um advogado.

Sheet Custo total
A1: ANTES DE FECHAR NEGÓCIO | CUSTO TOTAL DA COMPRA
A2: Preencha as células azuis. Valores de transferência ficam em branco de propósito: cada estado cobra valores diferentes.
A4: Item | B4: Valor | C4: Quem paga | D4: Observação
A5: 1. PREÇO
A6: Preço negociado (R$) | B6: 56500 | D6: O valor que você vai pagar pelo carro.
A7: 2. TRANSFERÊNCIA (valores variam por estado)
A8: Vistoria de transferência (R$) | D8: Consulte o órgão de trânsito do seu estado. [VERIFICAR]
A9: Taxa do órgão estadual de trânsito (R$) | D9: Consulte o órgão de trânsito do seu estado. [VERIFICAR]
A10: Reconhecimento de firma / assinatura, se aplicável (R$) | D10: Depende da forma de transferência do seu estado (papel ou eletrônica). [VERIFICAR]
A11: Despachante (opcional) (R$) | D11: Só se você optar por contratar.
A12: Subtotal transferência | B12: =SUM(B8:B11)
A13: 3. DÉBITOS PENDENTES DO VEÍCULO (combine quem paga)
A14: IPVA em aberto (R$) | B14: 0 | C14: Vendedor | D14: Consulte antes. Se o vendedor paga, exija quitação antes da transferência ou desconto no preço.
A15: Licenciamento em aberto (R$) | B15: 0 | C15: Vendedor
A16: Multas em aberto (R$) | B16: 195.23 | C16: Vendedor
A17: Débitos que ficam com você (comprador) | B17: =SUMIF(C14:C16,"Comprador",B14:B16) | D17: Soma só o que está marcado "Comprador".
A18: 4. PROTEÇÃO E DEIXAR O CARRO EM DIA
A19: Vistoria cautelar (R$) | B19: 350 | D19: Feita por vistoriador antes de pagar.
A20: Seguro: 1ª parcela (R$) | B20: 480 | D20: Contrate para valer a partir da retirada do carro.
A21: Seguro: valor anual (R$) | B21: 3600 | D21: Usado no custo do 1º ano e no orçamento mensal.
A22: Revisão pós-compra: óleo e filtros (R$) | B22: 600 | D22: Orçamento de oficina de confiança.
A23: Correias, se a km pedir (R$) | B23: 0 | D23: Siga o manual do fabricante para o intervalo.
A24: Pneus, se o laudo apontar (R$) | B24: 1600
A25: Freios, se o laudo apontar (R$) | B25: 0
A26: Outros reparos apontados (R$) | B26: 1200 | D26: Itens do laudo cautelar orçados em oficina.
A27: Subtotal logo após a compra (revisão e reparos) | B27: =SUM(B22:B26)
A28: 5. RESERVA DE IMPREVISTOS
A29: Reserva (% do preço) | B29: 0.1 | D29: Padrão 10%. Ajuste como preferir.
A30: Reserva de imprevistos (R$) | B30: =N($B$6)*N($B$29) | D30: Dinheiro separado, não é gasto certo.
A31: 6. SE FOR FINANCIAR
A32: Vai financiar? (Sim/Não) | B32: Sim | D32: "Não" zera os cálculos do financiamento.
A33: Entrada (R$) | B33: 20000
A34: Valor financiado (R$) | B34: =IF($B$32="Sim",MAX(0,N($B$6)-N($B$33)),0) | D34: Preço − entrada.
A35: Número de parcelas | B35: 48
A36: Taxa de juros ao mês (%) | B36: 0.019 | D36: Use a taxa informada por escrito. Compare propostas pelo CET (Custo Efetivo Total).
A37: Parcela mensal (R$) | B37: =IF(OR(NOT($B$32="Sim"),$B$34=0,N($B$35)<=0),0,IF(N($B$36)=0,$B$34/$B$35,PMT($B$36,$B$35,-$B$34))) | D37: Tabela Price (função PMT). A parcela real pode incluir tarifas, seguro e impostos.
A38: Total pago nas parcelas (R$) | B38: =$B$37*N($B$35) | D38: Parcela × número de parcelas.
A39: Custo do financiamento (juros) (R$) | B39: =IF($B$37=0,0,$B$38-$B$34) | D39: Total pago nas parcelas − valor financiado.
A40: 7. CUSTOS DE USO
A41: Alíquota de IPVA do seu estado (%) | B41: 0.04 | D41: Varia por estado e tipo de veículo. [VERIFICAR]
...

Sheet Orçamento mensal
A1: ANTES DE FECHAR NEGÓCIO | ORÇAMENTO MENSAL DO CARRO
A2: Quanto o carro vai custar por mês comparado com a sua renda disponível. É um indicador para você organizar as contas, não uma regra.
A4: Item | B4: Por mês (R$) | C4: De onde vem
A5: Renda mensal disponível (líquida) (R$) | B5: 6500 | C5: Quanto entra por mês, já descontados impostos.
A6: Limite que você define (% da renda) | B6: 0.2 | C6: Padrão 20%. É só uma referência pessoal; ajuste à sua realidade.
A7: CUSTOS MENSAIS DO CARRO
A8: Parcela do financiamento | B8: ='Custo total'!$B$37 | C8: Da aba Custo total (0 se não financiar).
A9: Seguro (valor anual ÷ 12) | B9: =MAX(N('Custo total'!$B$21),N('Custo total'!$B$20))/12 | C9: Da aba Custo total.
A10: IPVA estimado (÷ 12) | B10: ='Custo total'!$B$42/12 | C10: Da aba Custo total.
A11: Licenciamento (÷ 12) | B11: =N('Custo total'!$B$43)/12 | C11: Da aba Custo total.
A12: Manutenção | B12: =N('Custo total'!$B$44) | C12: Da aba Custo total.
A13: Combustível | B13: ='Custo total'!$B$48 | C13: Da aba Custo total.
A14: Estacionamento | B14: 150 | C14: Garagem, rotativo, condomínio.
A15: Pedágio, lavagem e outros | B15: 80
A16: CUSTO MENSAL DO CARRO | B16: =SUM(B8:B15) | C16: Soma dos itens acima.
A17: Quanto isso representa da sua renda | B17: =IF(N(B5)=0,"",B16/B5)
A18: Sobra da renda depois do carro | B18: =N(B5)-B16 | C18: Renda − custo mensal do carro.
A19: Indicador | B19: =IF(B17="","Informe sua renda disponível.",IF(B17>B6,"Acima do limite que você definiu: reveja o orçamento antes de fechar.","Dentro do limite que você definiu."))
A21: Quando o financiamento terminar, a parcela sai da conta. Manutenção tende a subir com a idade e a quilometragem do carro. O limite de % da renda é uma referência que você escolhe, não uma recomendação.
